<?xml version="1.0" encoding="UTF-8"?>
<testsuite name="LearnTestNG"
           tests="1"
           failures="1"
           errors="0"
           skipped="0"
           time="0.132">
    <properties></properties>

            <testcase
                name="SoftAssertions"
                time="0.132"
                classname="com.thetestingacademy.testng.assertion.MainClass">

            <failure type="java.lang.AssertionError" message="The following asserts failed:
	expected [2] but found [1]">
                <![CDATA[java.lang.AssertionError: The following asserts failed:
	expected [2] but found [1]
                org.testng.asserts.SoftAssert.assertAll(SoftAssert.java:46)org.testng.asserts.SoftAssert.assertAll(SoftAssert.java:30)com.thetestingacademy.testng.assertion.MainClass.SoftAssertions(MainClass.java:24)java.base/jdk.internal.reflect.NativeMethodAccessorImpl.invoke0(Native Method)java.base/jdk.internal.reflect.NativeMethodAccessorImpl.invoke(NativeMethodAccessorImpl.java:78)java.base/jdk.internal.reflect.DelegatingMethodAccessorImpl.invoke(DelegatingMethodAccessorImpl.java:43)java.base/java.lang.reflect.Method.invoke(Method.java:567)org.testng.internal.invokers.MethodInvocationHelper.invokeMethod(MethodInvocationHelper.java:139)org.testng.internal.invokers.TestInvoker.invokeMethod(TestInvoker.java:677)org.testng.internal.invokers.TestInvoker.invokeTestMethod(TestInvoker.java:221)org.testng.internal.invokers.MethodRunner.runInSequence(MethodRunner.java:50)org.testng.internal.invokers.TestInvoker$MethodInvocationAgent.invoke(TestInvoker.java:962)org.testng.internal.invokers.TestInvoker.invokeTestMethods(TestInvoker.java:194)org.testng.internal.invokers.TestMethodWorker.invokeTestMethods(TestMethodWorker.java:148)org.testng.internal.invokers.TestMethodWorker.run(TestMethodWorker.java:128)java.base/java.util.ArrayList.forEach(ArrayList.java:1511)org.testng.TestRunner.privateRun(TestRunner.java:806)org.testng.TestRunner.run(TestRunner.java:601)org.testng.SuiteRunner.runTest(SuiteRunner.java:433)org.testng.SuiteRunner.runSequentially(SuiteRunner.java:427)org.testng.SuiteRunner.privateRun(SuiteRunner.java:387)org.testng.SuiteRunner.run(SuiteRunner.java:330)org.testng.SuiteRunnerWorker.runSuite(SuiteRunnerWorker.java:52)org.testng.SuiteRunnerWorker.run(SuiteRunnerWorker.java:95)org.testng.TestNG.runSuitesSequentially(TestNG.java:1256)org.testng.TestNG.runSuitesLocally(TestNG.java:1176)org.testng.TestNG.runSuites(TestNG.java:1099)org.testng.TestNG.run(TestNG.java:1067)com.intellij.rt.testng.IDEARemoteTestNG.run(IDEARemoteTestNG.java:66)com.intellij.rt.testng.RemoteTestNGStarter.main(RemoteTestNGStarter.java:109)
]]>
            </failure>
    </testcase>


</testsuite>
